<mujoco model="Unitree Go2">
  <compiler angle="radian" meshdir="assets" autolimits="true"/>

  <option cone="elliptic" impratio="100" integrator="implicitfast" timestep="0.0005"/>

  <default>
    <default class="go2">
      <geom friction="0.6" margin="0.001" condim="1"/>
      <joint axis="0 1 0" damping="2" armature="0.01" frictionloss="0.2"/>

      <!-- Abduction Joint -->
      <default class="abduction">
        <joint axis="1 0 0" range="-1.0472 1.0472" actuatorfrcrange="-23.7 23.7"/>
        <position kp="60" kv="5" ctrllimited="true" ctrlrange="-1.0472 1.0472"/>
      </default>

      <!-- Front Hip Joints -->
      <default class="front_hip">
        <joint range="-1.5708 3.4907" actuatorfrcrange="-23.7 23.7"/>
        <position kp="60" kv="5" ctrllimited="true" ctrlrange="-1.5708 3.4907"/>
      </default>

      <!-- Back Hip Joints -->
      <default class="back_hip">
        <joint range="-0.5236 4.5379" actuatorfrcrange="-23.7 23.7"/>
        <position kp="60" kv="5" ctrllimited="true" ctrlrange="-0.5236 4.5379"/>
      </default>		
  
      <!-- Knee Joint -->
      <default class="knee">
        <joint range="-2.7227 -0.83776" actuatorfrcrange="-45.43 45.43"/>
        <position kp="60" kv="5" ctrllimited="true" ctrlrange="-2.7227 -0.83776"/>
      </default>
	  
      <!-- Visual -->
      <default class="visual">
        <geom type="mesh" contype="0" conaffinity="0" group="2"/>
      </default>

      <!-- Collision -->
      <default class="collision">
        <geom group="3"/>
        <default class="foot">
	        <geom size="0.022" pos="-0.002 0 -0.213" priority="1" solimp="0.015 1 0.022" condim="6" friction="0.8 0.02 0.01"/>
        </default>
      </default>
    </default>

    <default class="task">
      <site rgba="1 0 0 1" size=".02" group="5"/>
      <default class="flight">
        <site rgba="1 .3 .3 1" size="0.019" group="5"/>
      </default>
      <default class="stance">
        <site rgba=".3 1 .3 1" size=".018" group="4"/>
      </default>
    </default>
  </default>

  <asset>
    <material name="metal" rgba=".9 .95 .95 1" />
    <material name="black" rgba="0 0 0 1" />
    <material name="white" rgba="1 1 1 1" />
    <material name="gray" rgba="0.671705 0.692426 0.774270 1" />

    <mesh file="base_0.obj" />
    <mesh file="base_1.obj" />
    <mesh file="base_2.obj" />
    <mesh file="base_3.obj" />
    <mesh file="base_4.obj" />
    <mesh file="hip_0.obj" />
    <mesh file="hip_1.obj" />
    <mesh file="thigh_0.obj" />
    <mesh file="thigh_1.obj" />
    <mesh file="thigh_mirror_0.obj" />
    <mesh file="thigh_mirror_1.obj" />
    <mesh file="calf_0.obj" />
    <mesh file="calf_1.obj" />
    <mesh file="calf_mirror_0.obj" />
    <mesh file="calf_mirror_1.obj" />
    <mesh file="foot.obj" />
  </asset>
  
  <worldbody>
    <!-- GO2 robot with consistent names and inertial tuned to GO2 -->
    <body name="trunk" pos="0 0 0.445" childclass="go2"> 
      <inertial pos="0.021112 0 -0.005366" quat="-0.000543471 0.713435 -0.00173769 0.700719"
        mass="6.921"
        diaginertia="0.107027 0.0980771 0.0244531" />
      <freejoint/>

      <geom mesh="base_0" material="black" class="visual" />
      <geom mesh="base_1" material="black" class="visual" />
      <geom mesh="base_2" material="black" class="visual" />
      <geom mesh="base_3" material="white" class="visual" />
      <geom mesh="base_4" material="gray"  class="visual" />
      <geom size="0.1881 0.04675 0.057" type="box" class="collision" />
      <geom size="0.05 0.045" pos="0.285 0 0.01" type="cylinder" class="collision" />
      <geom size="0.047" pos="0.293 0 -0.06" class="collision" />

      <site name="imu" pos="-0.02557 0 0.04232" />

      <!-- mjpc compatibility -->
      <site name="torso"/>
      <site name="head" pos=".3 0 0" class="task" size="5"/>

      <!-- Front Left Leg -->
      <body name="FL_hip" pos="0.1934 0.0465 0">
        <inertial pos="-0.0054 0.00194 -0.000105" quat="0.497014 0.499245 0.505462 0.498237"
          mass="0.678"
          diaginertia="0.00088403 0.000596003 0.000479967" />
        <joint name="FL_hip_joint" class="abduction" />
        <geom mesh="hip_0" material="metal" class="visual" />
        <geom mesh="hip_1" material="gray" class="visual" />
        <geom size="0.046 0.02" pos="0 0.08 0" quat="1 1 0 0" type="cylinder" class="collision" />
        <body name="FL_thigh" pos="0 0.0955 0">
          <inertial pos="-0.00374 -0.0223 -0.0327" quat="0.829533 0.0847635 -0.0200632 0.551623"
            mass="1.152"
            diaginertia="0.00594973 0.00584149 0.000878787" />
          <joint name="FL_thigh_joint" class="front_hip" />
          <geom mesh="thigh_0" material="metal" class="visual" />
          <geom mesh="thigh_1" material="gray" class="visual" />
          <geom size="0.1065 0.01225 0.017" pos="0 0 -0.1065" quat="0.707107 0 0.707107 0"
            type="box" class="collision" />
          <body name="FL_calf" pos="0 0 -0.213">
            <inertial pos="0.00629595 -0.000622121 -0.141417"
              quat="0.710672 0.00154099 -0.00450087 0.703508"
              mass="0.241352" diaginertia="0.0014901 0.00146356 5.31397e-05" />
            <joint name="FL_calf_joint" class="knee" />
            <geom mesh="calf_0" material="gray" class="visual" />
            <geom mesh="calf_1" material="black" class="visual" />
            <geom size="0.012 0.06" pos="0.008 0 -0.06" quat="0.994493 0 -0.104807 0"
              type="cylinder" class="collision" />
            <geom size="0.011 0.0325" pos="0.02 0 -0.148" quat="0.999688 0 0.0249974 0"
              type="cylinder" class="collision" />
              
            <geom pos="0 0 -0.213" mesh="foot" class="visual" material="black" />
            <geom name="FL" class="foot" />
            <body name="FL_foot" pos="0 0 -0.213" />
            <site name="FL" pos="0 0 -0.213" />
          </body>
        </body>
      </body>
      
      <!-- Front Right Leg -->
      <body name="FR_hip" pos="0.1934 -0.0465 0">
        <inertial pos="-0.0054 -0.00194 -0.000105" quat="0.498237 0.505462 0.499245 0.497014"
          mass="0.678"
          diaginertia="0.00088403 0.000596003 0.000479967" />
        <joint name="FR_hip_joint" class="abduction" />
        <geom mesh="hip_0" material="metal" class="visual" quat="4.63268e-05 1 0 0" />
        <geom mesh="hip_1" material="gray" class="visual" quat="4.63268e-05 1 0 0" />
        <geom size="0.046 0.02" pos="0 -0.08 0" quat="0.707107 0.707107 0 0" type="cylinder"
          class="collision" />
        <body name="FR_thigh" pos="0 -0.0955 0">
          <inertial pos="-0.00374 0.0223 -0.0327" quat="0.551623 -0.0200632 0.0847635 0.829533"
            mass="1.152"
            diaginertia="0.00594973 0.00584149 0.000878787" />
          <joint name="FR_thigh_joint" class="front_hip" />
          <geom mesh="thigh_mirror_0" material="metal" class="visual" />
          <geom mesh="thigh_mirror_1" material="gray" class="visual" />
          <geom size="0.1065 0.01225 0.017" pos="0 0 -0.1065" quat="0.707107 0 0.707107 0"
            type="box" class="collision" />
          <body name="FR_calf" pos="0 0 -0.213">
            <inertial pos="0.00629595 0.000622121 -0.141417"
              quat="0.703508 -0.00450087 0.00154099 0.710672"
              mass="0.241352" diaginertia="0.0014901 0.00146356 5.31397e-05" />
            <joint name="FR_calf_joint" class="knee" />
            <geom mesh="calf_mirror_0" material="gray" class="visual" />
            <geom mesh="calf_mirror_1" material="black" class="visual" />
            <geom size="0.013 0.06" pos="0.01 0 -0.06" quat="0.995004 0 -0.0998334 0"
              type="cylinder" class="collision" />
            <geom size="0.011 0.0325" pos="0.02 0 -0.148" quat="0.999688 0 0.0249974 0"
              type="cylinder" class="collision" />
            <geom pos="0 0 -0.213" mesh="foot" class="visual" material="black" />
            <geom name="FR" class="foot" />
            <body name="FR_foot" pos="0 0 -0.213" />

            <site name="FR" pos="0 0 -0.213" />
          </body>
        </body>
      </body>

      <!-- Hind Left Leg (HL) -->
      <body name="HL_hip" pos="-0.1934 0.0465 0">
        <inertial pos="0.0054 0.00194 -0.000105" quat="0.505462 0.498237 0.497014 0.499245"
          mass="0.678"
          diaginertia="0.00088403 0.000596003 0.000479967" />
        <joint name="HL_hip_joint" class="abduction" />
        <geom mesh="hip_0" material="metal" class="visual" quat="4.63268e-05 0 1 0" />
        <geom mesh="hip_1" material="gray" class="visual" quat="4.63268e-05 0 1 0" />
        <geom size="0.046 0.02" pos="0 0.08 0" quat="0.707107 0.707107 0 0" type="cylinder"
          class="collision" />
        <body name="HL_thigh" pos="0 0.0955 0">
          <inertial pos="-0.00374 -0.0223 -0.0327" quat="0.829533 0.0847635 -0.0200632 0.551623"
            mass="1.152"
            diaginertia="0.00594973 0.00584149 0.000878787" />
          <joint name="HL_thigh_joint" class="back_hip" />
          <geom mesh="thigh_0" material="metal" class="visual" />
          <geom mesh="thigh_1" material="gray" class="visual" />
          <geom size="0.1065 0.01225 0.017" pos="0 0 -0.1065" quat="0.707107 0 0.707107 0"
            type="box" class="collision" />
          <body name="HL_calf" pos="0 0 -0.213">
            <inertial pos="0.00629595 -0.000622121 -0.141417"
              quat="0.710672 0.00154099 -0.00450087 0.703508"
              mass="0.241352" diaginertia="0.0014901 0.00146356 5.31397e-05" />
            <joint name="HL_calf_joint" class="knee" />
            <geom mesh="calf_0" material="gray" class="visual" />
            <geom mesh="calf_1" material="black" class="visual" />
            <geom size="0.013 0.06" pos="0.01 0 -0.06" quat="0.995004 0 -0.0998334 0"
              type="cylinder" class="collision" />
            <geom size="0.011 0.0325" pos="0.02 0 -0.148" quat="0.999688 0 0.0249974 0"
              type="cylinder" class="collision" />
            <geom pos="0 0 -0.213" mesh="foot" class="visual" material="black" />
            <geom name="HL" class="foot" />
            <body name="HL_foot" pos="0 0 -0.213" />
            
            <site name="HL" pos="0 0 -0.213" />
          </body>
        </body>
      </body>

      <!-- Hind Right Leg (HR) -->
      <body name="HR_hip" pos="-0.1934 -0.0465 0">
        <inertial pos="0.0054 -0.00194 -0.000105" quat="0.499245 0.497014 0.498237 0.505462"
          mass="0.678"
          diaginertia="0.00088403 0.000596003 0.000479967" />
        <joint name="HR_hip_joint" class="abduction" />
        <geom mesh="hip_0" material="metal" class="visual"
          quat="2.14617e-09 4.63268e-05 4.63268e-05 -1" />
        <geom mesh="hip_1" material="gray" class="visual"
          quat="2.14617e-09 4.63268e-05 4.63268e-05 -1" />
        <geom size="0.046 0.02" pos="0 -0.08 0" quat="0.707107 0.707107 0 0" type="cylinder"
          class="collision" />
        <body name="HR_thigh" pos="0 -0.0955 0">
          <inertial pos="-0.00374 0.0223 -0.0327" quat="0.551623 -0.0200632 0.0847635 0.829533"
            mass="1.152"
            diaginertia="0.00594973 0.00584149 0.000878787" />
          <joint name="HR_thigh_joint" class="back_hip" />
          <geom mesh="thigh_mirror_0" material="metal" class="visual" />
          <geom mesh="thigh_mirror_1" material="gray" class="visual" />
          <geom size="0.1065 0.01225 0.017" pos="0 0 -0.1065" quat="0.707107 0 0.707107 0"
            type="box" class="collision" />
          <body name="HR_calf" pos="0 0 -0.213">
            <inertial pos="0.00629595 0.000622121 -0.141417"
              quat="0.703508 -0.00450087 0.00154099 0.710672"
              mass="0.241352" diaginertia="0.0014901 0.00146356 5.31397e-05" />
            <joint name="HR_calf_joint" class="knee" />
            <geom mesh="calf_mirror_0" material="gray" class="visual" />
            <geom mesh="calf_mirror_1" material="black" class="visual" />
            <geom size="0.013 0.06" pos="0.01 0 -0.06" quat="0.995004 0 -0.0998334 0"
              type="cylinder" class="collision" />
            <geom size="0.011 0.0325" pos="0.02 0 -0.148" quat="0.999688 0 0.0249974 0"
              type="cylinder" class="collision" />
            <geom pos="0 0 -0.213" mesh="foot" class="visual" material="black" />
            <geom name="HR" class="foot" />
            <body name="HR_foot" pos="0 0 -0.213" />

            <site name="HR" pos="0 0 -0.213" />
          </body>
        </body>
      </body>
    </body>
  </worldbody>


<!-- Sensors -->
<sensor> 
    <user name="Upright" dim="3" user="6 1 0 3 0.05"/>
    <user name="Height" dim="1" user="6 1 0 3 0.04"/>
    <user name="Position" dim="3" user="2 0.2 0 0.5 0.1"/>
    <user name="Gait" dim="4" user="6 2 0 10 0.03"/>
    <user name="Balance" dim="2" user="2 0.2 0 0.3 0.1"/>
    <user name="Effort" dim="12" user="0 0.03 0.0 0.1"/>
    <user name="Posture" dim="12" user="0 0.02 0.0 0.1"/>
    <user name="Orientation" dim="2" user="0 0 0 .03"/>
    <user name="Angmom" dim="3" user="0 0 0 .03"/>

    <jointpos name="pos_FR_hip_joint" joint="FR_hip_joint"/>
    <jointpos name="pos_FR_thigh_joint" joint="FR_thigh_joint"/>
    <jointpos name="pos_FR_calf_joint" joint="FR_calf_joint"/>
    <jointpos name="pos_FL_hip_joint" joint="FL_hip_joint"/>
    <jointpos name="pos_FL_thigh_joint" joint="FL_thigh_joint"/>
    <jointpos name="pos_FL_calf_joint" joint="FL_calf_joint"/>
    <jointpos name="pos_HR_hip_joint" joint="HR_hip_joint"/>
    <jointpos name="pos_HR_thigh_joint" joint="HR_thigh_joint"/>
    <jointpos name="pos_HR_calf_joint" joint="HR_calf_joint"/>
    <jointpos name="pos_HL_hip_joint" joint="HL_hip_joint"/>
    <jointpos name="pos_HL_thigh_joint" joint="HL_thigh_joint"/>
    <jointpos name="pos_HL_calf_joint" joint="HL_calf_joint"/>

    <jointvel name="FR_hip_vel" joint="FR_hip_joint" />
    <jointvel name="FR_thigh_vel" joint="FR_thigh_joint" />
    <jointvel name="FR_calf_vel" joint="FR_calf_joint" />
    <jointvel name="FL_hip_vel" joint="FL_hip_joint" />
    <jointvel name="FL_thigh_vel" joint="FL_thigh_joint" />
    <jointvel name="FL_calf_vel" joint="FL_calf_joint" />
    <jointvel name="HR_hip_vel" joint="HR_hip_joint" />
    <jointvel name="HR_thigh_vel" joint="HR_thigh_joint" />
    <jointvel name="HR_calf_vel" joint="HR_calf_joint" />
    <jointvel name="HL_hip_vel" joint="HL_hip_joint" />
    <jointvel name="HL_thigh_vel" joint="HL_thigh_joint" />
    <jointvel name="HL_calf_vel" joint="HL_calf_joint" />

    <jointactuatorfrc name="FR_hip_torque" joint="FR_hip_joint" noise="0.01" />
    <jointactuatorfrc name="FR_thigh_torque" joint="FR_thigh_joint" noise="0.01" />
    <jointactuatorfrc name="FR_calf_torque" joint="FR_calf_joint" noise="0.01" />
    <jointactuatorfrc name="FL_hip_torque" joint="FL_hip_joint" noise="0.01" />
    <jointactuatorfrc name="FL_thigh_torque" joint="FL_thigh_joint" noise="0.01" />
    <jointactuatorfrc name="FL_calf_torque" joint="FL_calf_joint" noise="0.01" />
    <jointactuatorfrc name="HR_hip_torque" joint="HR_hip_joint" noise="0.01" />
    <jointactuatorfrc name="HR_thigh_torque" joint="HR_thigh_joint" noise="0.01" />
    <jointactuatorfrc name="HR_calf_torque" joint="HR_calf_joint" noise="0.01" />
    <jointactuatorfrc name="HL_hip_torque" joint="HL_hip_joint" noise="0.01" />
    <jointactuatorfrc name="HL_thigh_torque" joint="HL_thigh_joint" noise="0.01" />
    <jointactuatorfrc name="HL_calf_torque" joint="HL_calf_joint" noise="0.01" />

    <framequat name="imu_quat" objtype="site" objname="imu"/>
    <gyro name="imu_gyro" site="imu"/>
    <accelerometer name="imu_acc" site="imu"/>

    <framepos name="frame_pos" objtype="site" objname="imu"/>
    <framelinvel name="frame_vel" objtype="site" objname="imu"/>

    <!-- mjpc -->
    <framepos name="torso_pos" objtype="site" objname="torso"/>
    <framepos name="FR_pos" objtype="site" objname="FR"/>
    <framepos name="FL_pos" objtype="site" objname="FL"/>
    <framepos name="HR_pos" objtype="site" objname="HR"/>
    <framepos name="HL_pos" objtype="site" objname="HL"/>
    <framepos name="trace0" objtype="site" objname="head"/>

    <touch name="FR_touch" site="FR"/>
    <touch name="FL_touch" site="FL"/>
    <touch name="HR_touch" site="HR"/>
    <touch name="HL_touch" site="HL"/>

    <subtreecom name="torso_subtreecom" body="trunk"/>
    <subtreelinvel name="torso_subtreelinvel" body="trunk"/>
    <subtreelinvel name="torso_angmom" body="trunk"/>
</sensor>


<actuator>	
	<position class="abduction" name="FR_hip" joint="FR_hip_joint"/>
	<position class="front_hip" name="FR_thigh" joint="FR_thigh_joint"/>
	<position class="knee" name="FR_calf" joint="FR_calf_joint"/>
	<position class="abduction" name="FL_hip" joint="FL_hip_joint"/>
	<position class="front_hip" name="FL_thigh" joint="FL_thigh_joint"/>
	<position class="knee" name="FL_calf" joint="FL_calf_joint"/>
	<position class="abduction" name="HR_hip" joint="HR_hip_joint"/>
	<position class="back_hip" name="HR_thigh" joint="HR_thigh_joint"/>
	<position class="knee" name="HR_calf" joint="HR_calf_joint"/>
	<position class="abduction" name="HL_hip" joint="HL_hip_joint"/>
	<position class="back_hip" name="HL_thigh" joint="HL_thigh_joint"/>
	<position class="knee" name="HL_calf" joint="HL_calf_joint"/>
</actuator>


</mujoco>
